[2024-06-04T16:57:45.331+0000] {local_task_job_runner.py:120} INFO - ::group::Pre task execution logs
[2024-06-04T16:57:45.365+0000] {taskinstance.py:2076} INFO - Dependencies all met for dep_context=non-requeueable deps ti=<TaskInstance: dag_ETL_directions.transform_load_directions_data manual__2024-06-04T16:57:30.608849+00:00 [queued]>
[2024-06-04T16:57:45.380+0000] {taskinstance.py:2076} INFO - Dependencies all met for dep_context=requeueable deps ti=<TaskInstance: dag_ETL_directions.transform_load_directions_data manual__2024-06-04T16:57:30.608849+00:00 [queued]>
[2024-06-04T16:57:45.381+0000] {taskinstance.py:2306} INFO - Starting attempt 1 of 4
[2024-06-04T16:57:45.409+0000] {taskinstance.py:2330} INFO - Executing <Task(PythonOperator): transform_load_directions_data> on 2024-06-04 16:57:30.608849+00:00
[2024-06-04T16:57:45.422+0000] {warnings.py:110} WARNING - /home/***/.local/lib/python3.12/site-packages/***/task/task_runner/standard_task_runner.py:61: DeprecationWarning: This process (pid=112) is multi-threaded, use of fork() may lead to deadlocks in the child.
  pid = os.fork()

[2024-06-04T16:57:45.426+0000] {standard_task_runner.py:63} INFO - Started process 114 to run task
[2024-06-04T16:57:45.427+0000] {standard_task_runner.py:90} INFO - Running: ['***', 'tasks', 'run', 'dag_ETL_directions', 'transform_load_directions_data', 'manual__2024-06-04T16:57:30.608849+00:00', '--job-id', '60', '--raw', '--subdir', 'DAGS_FOLDER/dag_ETL_directions.py', '--cfg-path', '/tmp/tmpbaxzyxoh']
[2024-06-04T16:57:45.431+0000] {standard_task_runner.py:91} INFO - Job 60: Subtask transform_load_directions_data
[2024-06-04T16:57:45.522+0000] {task_command.py:426} INFO - Running <TaskInstance: dag_ETL_directions.transform_load_directions_data manual__2024-06-04T16:57:30.608849+00:00 [running]> on host 6b740a15ab9e
[2024-06-04T16:57:45.827+0000] {taskinstance.py:2648} INFO - Exporting env vars: AIRFLOW_CTX_DAG_OWNER='Matheus' AIRFLOW_CTX_DAG_ID='dag_ETL_directions' AIRFLOW_CTX_TASK_ID='transform_load_directions_data' AIRFLOW_CTX_EXECUTION_DATE='2024-06-04T16:57:30.608849+00:00' AIRFLOW_CTX_TRY_NUMBER='1' AIRFLOW_CTX_DAG_RUN_ID='manual__2024-06-04T16:57:30.608849+00:00'
[2024-06-04T16:57:45.832+0000] {taskinstance.py:430} INFO - ::endgroup::
[2024-06-04T16:57:45.887+0000] {base.py:84} INFO - Using connection ID 'postgres_conn' for task execution.
[2024-06-04T16:57:46.011+0000] {taskinstance.py:441} INFO - ::group::Post task execution logs
[2024-06-04T16:57:46.013+0000] {taskinstance.py:2905} ERROR - Task failed with exception
Traceback (most recent call last):
  File "/home/airflow/.local/lib/python3.12/site-packages/airflow/models/taskinstance.py", line 465, in _execute_task
    result = _execute_callable(context=context, **execute_callable_kwargs)
             ^^^^^^^^^^^^^^^^^^^^^^^^^^^^^^^^^^^^^^^^^^^^^^^^^^^^^^^^^^^^^
  File "/home/airflow/.local/lib/python3.12/site-packages/airflow/models/taskinstance.py", line 432, in _execute_callable
    return execute_callable(context=context, **execute_callable_kwargs)
           ^^^^^^^^^^^^^^^^^^^^^^^^^^^^^^^^^^^^^^^^^^^^^^^^^^^^^^^^^^^^
  File "/home/airflow/.local/lib/python3.12/site-packages/airflow/models/baseoperator.py", line 400, in wrapper
    return func(self, *args, **kwargs)
           ^^^^^^^^^^^^^^^^^^^^^^^^^^^
  File "/home/airflow/.local/lib/python3.12/site-packages/airflow/operators/python.py", line 235, in execute
    return_value = self.execute_callable()
                   ^^^^^^^^^^^^^^^^^^^^^^^
  File "/home/airflow/.local/lib/python3.12/site-packages/airflow/operators/python.py", line 252, in execute_callable
    return self.python_callable(*self.op_args, **self.op_kwargs)
           ^^^^^^^^^^^^^^^^^^^^^^^^^^^^^^^^^^^^^^^^^^^^^^^^^^^^^
  File "/opt/airflow/dags/dag_ETL_directions.py", line 52, in transform_load_data
    df_data.to_sql("tb_directions", engine, method=None, index = False)
  File "/home/airflow/.local/lib/python3.12/site-packages/pandas/util/_decorators.py", line 333, in wrapper
    return func(*args, **kwargs)
           ^^^^^^^^^^^^^^^^^^^^^
  File "/home/airflow/.local/lib/python3.12/site-packages/pandas/core/generic.py", line 3008, in to_sql
    return sql.to_sql(
           ^^^^^^^^^^^
  File "/home/airflow/.local/lib/python3.12/site-packages/pandas/io/sql.py", line 788, in to_sql
    return pandas_sql.to_sql(
           ^^^^^^^^^^^^^^^^^^
  File "/home/airflow/.local/lib/python3.12/site-packages/pandas/io/sql.py", line 1948, in to_sql
    table = self.prep_table(
            ^^^^^^^^^^^^^^^^
  File "/home/airflow/.local/lib/python3.12/site-packages/pandas/io/sql.py", line 1852, in prep_table
    table.create()
  File "/home/airflow/.local/lib/python3.12/site-packages/pandas/io/sql.py", line 927, in create
    raise ValueError(f"Table '{self.name}' already exists.")
ValueError: Table 'tb_directions' already exists.
[2024-06-04T16:57:46.058+0000] {taskinstance.py:1206} INFO - Marking task as UP_FOR_RETRY. dag_id=dag_ETL_directions, task_id=transform_load_directions_data, run_id=manual__2024-06-04T16:57:30.608849+00:00, execution_date=20240604T165730, start_date=20240604T165745, end_date=20240604T165746
[2024-06-04T16:57:46.092+0000] {standard_task_runner.py:110} ERROR - Failed to execute job 60 for task transform_load_directions_data (Table 'tb_directions' already exists.; 114)
[2024-06-04T16:57:46.128+0000] {local_task_job_runner.py:240} INFO - Task exited with return code 1
[2024-06-04T16:57:46.154+0000] {taskinstance.py:3498} INFO - 0 downstream tasks scheduled from follow-on schedule check
[2024-06-04T16:57:46.156+0000] {local_task_job_runner.py:222} INFO - ::endgroup::
