[2024-06-04T17:01:50.442+0000] {local_task_job_runner.py:120} INFO - ::group::Pre task execution logs
[2024-06-04T17:01:50.459+0000] {taskinstance.py:2076} INFO - Dependencies all met for dep_context=non-requeueable deps ti=<TaskInstance: dag_ETL_directions.transform_load_directions_data manual__2024-06-04T16:57:30.608849+00:00 [queued]>
[2024-06-04T17:01:50.469+0000] {taskinstance.py:2076} INFO - Dependencies all met for dep_context=requeueable deps ti=<TaskInstance: dag_ETL_directions.transform_load_directions_data manual__2024-06-04T16:57:30.608849+00:00 [queued]>
[2024-06-04T17:01:50.470+0000] {taskinstance.py:2306} INFO - Starting attempt 3 of 4
[2024-06-04T17:01:50.484+0000] {taskinstance.py:2330} INFO - Executing <Task(PythonOperator): transform_load_directions_data> on 2024-06-04 16:57:30.608849+00:00
[2024-06-04T17:01:50.490+0000] {warnings.py:110} WARNING - /home/***/.local/lib/python3.12/site-packages/***/task/task_runner/standard_task_runner.py:61: DeprecationWarning: This process (pid=167) is multi-threaded, use of fork() may lead to deadlocks in the child.
  pid = os.fork()

[2024-06-04T17:01:50.492+0000] {standard_task_runner.py:63} INFO - Started process 169 to run task
[2024-06-04T17:01:50.492+0000] {standard_task_runner.py:90} INFO - Running: ['***', 'tasks', 'run', 'dag_ETL_directions', 'transform_load_directions_data', 'manual__2024-06-04T16:57:30.608849+00:00', '--job-id', '62', '--raw', '--subdir', 'DAGS_FOLDER/dag_ETL_directions.py', '--cfg-path', '/tmp/tmpl9nc9juw']
[2024-06-04T17:01:50.494+0000] {standard_task_runner.py:91} INFO - Job 62: Subtask transform_load_directions_data
[2024-06-04T17:01:50.550+0000] {task_command.py:426} INFO - Running <TaskInstance: dag_ETL_directions.transform_load_directions_data manual__2024-06-04T16:57:30.608849+00:00 [running]> on host 6b740a15ab9e
[2024-06-04T17:01:50.644+0000] {taskinstance.py:2648} INFO - Exporting env vars: AIRFLOW_CTX_DAG_OWNER='Matheus' AIRFLOW_CTX_DAG_ID='dag_ETL_directions' AIRFLOW_CTX_TASK_ID='transform_load_directions_data' AIRFLOW_CTX_EXECUTION_DATE='2024-06-04T16:57:30.608849+00:00' AIRFLOW_CTX_TRY_NUMBER='3' AIRFLOW_CTX_DAG_RUN_ID='manual__2024-06-04T16:57:30.608849+00:00'
[2024-06-04T17:01:50.646+0000] {taskinstance.py:430} INFO - ::endgroup::
[2024-06-04T17:01:50.669+0000] {base.py:84} INFO - Using connection ID 'postgres_conn' for task execution.
[2024-06-04T17:01:50.754+0000] {taskinstance.py:441} INFO - ::group::Post task execution logs
[2024-06-04T17:01:50.755+0000] {taskinstance.py:2905} ERROR - Task failed with exception
Traceback (most recent call last):
  File "/home/airflow/.local/lib/python3.12/site-packages/sqlalchemy/engine/base.py", line 1910, in _execute_context
    self.dialect.do_execute(
  File "/home/airflow/.local/lib/python3.12/site-packages/sqlalchemy/engine/default.py", line 736, in do_execute
    cursor.execute(statement, parameters)
psycopg2.errors.UndefinedColumn: column "Travel_distance" of relation "tb_directions" does not exist
LINE 1: INSERT INTO tb_directions ("Travel_distance", "Travel_durati...
                                   ^


The above exception was the direct cause of the following exception:

Traceback (most recent call last):
  File "/home/airflow/.local/lib/python3.12/site-packages/airflow/models/taskinstance.py", line 465, in _execute_task
    result = _execute_callable(context=context, **execute_callable_kwargs)
             ^^^^^^^^^^^^^^^^^^^^^^^^^^^^^^^^^^^^^^^^^^^^^^^^^^^^^^^^^^^^^
  File "/home/airflow/.local/lib/python3.12/site-packages/airflow/models/taskinstance.py", line 432, in _execute_callable
    return execute_callable(context=context, **execute_callable_kwargs)
           ^^^^^^^^^^^^^^^^^^^^^^^^^^^^^^^^^^^^^^^^^^^^^^^^^^^^^^^^^^^^
  File "/home/airflow/.local/lib/python3.12/site-packages/airflow/models/baseoperator.py", line 400, in wrapper
    return func(self, *args, **kwargs)
           ^^^^^^^^^^^^^^^^^^^^^^^^^^^
  File "/home/airflow/.local/lib/python3.12/site-packages/airflow/operators/python.py", line 235, in execute
    return_value = self.execute_callable()
                   ^^^^^^^^^^^^^^^^^^^^^^^
  File "/home/airflow/.local/lib/python3.12/site-packages/airflow/operators/python.py", line 252, in execute_callable
    return self.python_callable(*self.op_args, **self.op_kwargs)
           ^^^^^^^^^^^^^^^^^^^^^^^^^^^^^^^^^^^^^^^^^^^^^^^^^^^^^
  File "/opt/airflow/dags/dag_ETL_directions.py", line 52, in transform_load_data
    df_data.to_sql("tb_directions", engine, if_exists = 'append', method=None, index = False)
  File "/home/airflow/.local/lib/python3.12/site-packages/pandas/util/_decorators.py", line 333, in wrapper
    return func(*args, **kwargs)
           ^^^^^^^^^^^^^^^^^^^^^
  File "/home/airflow/.local/lib/python3.12/site-packages/pandas/core/generic.py", line 3008, in to_sql
    return sql.to_sql(
           ^^^^^^^^^^^
  File "/home/airflow/.local/lib/python3.12/site-packages/pandas/io/sql.py", line 788, in to_sql
    return pandas_sql.to_sql(
           ^^^^^^^^^^^^^^^^^^
  File "/home/airflow/.local/lib/python3.12/site-packages/pandas/io/sql.py", line 1958, in to_sql
    total_inserted = sql_engine.insert_records(
                     ^^^^^^^^^^^^^^^^^^^^^^^^^^
  File "/home/airflow/.local/lib/python3.12/site-packages/pandas/io/sql.py", line 1507, in insert_records
    raise err
  File "/home/airflow/.local/lib/python3.12/site-packages/pandas/io/sql.py", line 1498, in insert_records
    return table.insert(chunksize=chunksize, method=method)
           ^^^^^^^^^^^^^^^^^^^^^^^^^^^^^^^^^^^^^^^^^^^^^^^^
  File "/home/airflow/.local/lib/python3.12/site-packages/pandas/io/sql.py", line 1059, in insert
    num_inserted = exec_insert(conn, keys, chunk_iter)
                   ^^^^^^^^^^^^^^^^^^^^^^^^^^^^^^^^^^^
  File "/home/airflow/.local/lib/python3.12/site-packages/pandas/io/sql.py", line 951, in _execute_insert
    result = conn.execute(self.table.insert(), data)
             ^^^^^^^^^^^^^^^^^^^^^^^^^^^^^^^^^^^^^^^
  File "/home/airflow/.local/lib/python3.12/site-packages/sqlalchemy/engine/base.py", line 1385, in execute
    return meth(self, multiparams, params, _EMPTY_EXECUTION_OPTS)
           ^^^^^^^^^^^^^^^^^^^^^^^^^^^^^^^^^^^^^^^^^^^^^^^^^^^^^^
  File "/home/airflow/.local/lib/python3.12/site-packages/sqlalchemy/sql/elements.py", line 334, in _execute_on_connection
    return connection._execute_clauseelement(
           ^^^^^^^^^^^^^^^^^^^^^^^^^^^^^^^^^^
  File "/home/airflow/.local/lib/python3.12/site-packages/sqlalchemy/engine/base.py", line 1577, in _execute_clauseelement
    ret = self._execute_context(
          ^^^^^^^^^^^^^^^^^^^^^^
  File "/home/airflow/.local/lib/python3.12/site-packages/sqlalchemy/engine/base.py", line 1953, in _execute_context
    self._handle_dbapi_exception(
  File "/home/airflow/.local/lib/python3.12/site-packages/sqlalchemy/engine/base.py", line 2134, in _handle_dbapi_exception
    util.raise_(
  File "/home/airflow/.local/lib/python3.12/site-packages/sqlalchemy/util/compat.py", line 211, in raise_
    raise exception
  File "/home/airflow/.local/lib/python3.12/site-packages/sqlalchemy/engine/base.py", line 1910, in _execute_context
    self.dialect.do_execute(
  File "/home/airflow/.local/lib/python3.12/site-packages/sqlalchemy/engine/default.py", line 736, in do_execute
    cursor.execute(statement, parameters)
sqlalchemy.exc.ProgrammingError: (psycopg2.errors.UndefinedColumn) column "Travel_distance" of relation "tb_directions" does not exist
LINE 1: INSERT INTO tb_directions ("Travel_distance", "Travel_durati...
                                   ^

[SQL: INSERT INTO tb_directions ("Travel_distance", "Travel_duration", "Destination", "Origin", "Summary_highway", "Time") VALUES (%(Travel_distance)s, %(Travel_duration)s, %(Destination)s, %(Origin)s, %(Summary_highway)s, %(Time)s)]
[parameters: {'Travel_distance': 19669, 'Travel_duration': 27, 'Destination': 'Matias Barbosa, State of Minas Gerais, 36120-000, Brazil', 'Origin': 'Juiz de Fora, State of Minas Gerais, Brazil', 'Summary_highway': 'BR-267 and Estr. União Indústria', 'Time': '2024-06-04 14:01:50'}]
(Background on this error at: https://sqlalche.me/e/14/f405)
[2024-06-04T17:01:50.781+0000] {taskinstance.py:1206} INFO - Marking task as UP_FOR_RETRY. dag_id=dag_ETL_directions, task_id=transform_load_directions_data, run_id=manual__2024-06-04T16:57:30.608849+00:00, execution_date=20240604T165730, start_date=20240604T170150, end_date=20240604T170150
[2024-06-04T17:01:50.794+0000] {standard_task_runner.py:110} ERROR - Failed to execute job 62 for task transform_load_directions_data ((psycopg2.errors.UndefinedColumn) column "Travel_distance" of relation "tb_directions" does not exist
LINE 1: INSERT INTO tb_directions ("Travel_distance", "Travel_durati...
                                   ^

[SQL: INSERT INTO tb_directions ("Travel_distance", "Travel_duration", "Destination", "Origin", "Summary_highway", "Time") VALUES (%(Travel_distance)s, %(Travel_duration)s, %(Destination)s, %(Origin)s, %(Summary_highway)s, %(Time)s)]
[parameters: {'Travel_distance': 19669, 'Travel_duration': 27, 'Destination': 'Matias Barbosa, State of Minas Gerais, 36120-000, Brazil', 'Origin': 'Juiz de Fora, State of Minas Gerais, Brazil', 'Summary_highway': 'BR-267 and Estr. União Indústria', 'Time': '2024-06-04 14:01:50'}]
(Background on this error at: https://sqlalche.me/e/14/f405); 169)
[2024-06-04T17:01:50.829+0000] {local_task_job_runner.py:240} INFO - Task exited with return code 1
[2024-06-04T17:01:50.845+0000] {taskinstance.py:3498} INFO - 0 downstream tasks scheduled from follow-on schedule check
[2024-06-04T17:01:50.847+0000] {local_task_job_runner.py:222} INFO - ::endgroup::
