[2024-06-04T12:34:07.676+0000] {task_context_logger.py:104} ERROR - Executor reports task instance <TaskInstance: dag_ETL_weather.weather_api_ready_origin scheduled__2024-05-24T00:05:00+00:00 [queued]> finished (failed) although the task says it's queued. (Info: None) Was the task killed externally?
